<sdf version='1.6'>
  <model name='wall_fb_1r1p'>
    <link name='first_link'>
      <gravity>0</gravity>
      <pose frame=''>0 0 0.55 0 -0 0</pose>
      <inertial>
        <pose frame=''>0 0.1375 0 0 -0 0</pose>
        <mass>1</mass>
        <inertia>
          <ixx>1</ixx>
          <ixy>0</ixy>
          <ixz>0</ixz>
          <iyy>1</iyy>
          <iyz>0</iyz>
          <izz>1</izz>
        </inertia>
      </inertial>
      <collision name='first_link_collision'>
        <pose frame=''>0 0 -0.01255 0 -0 0</pose>
        <geometry>
          <cylinder>
            <length>0.025</length>
            <radius>0.025</radius>
          </cylinder>
        </geometry>
      </collision>
      <collision name='first_link_collision_1'>
        <pose frame=''>0 0.05 -0.0125 0 -0 0</pose>
        <geometry>
          <box>
            <size>0.05 0.1 0.025</size>
          </box>
        </geometry>
      </collision>
      <collision name='first_link_collision_2'>
        <pose frame=''>0 0.15 0 0 -0 0</pose>
        <geometry>
          <box>
            <size>0.05 0.2 0.05</size>
          </box>
        </geometry>
      </collision>

      <visual name='first_link_visual'>
        <pose frame=''>0 0 -0.0125 0 -0 0</pose>
        <geometry>
          <cylinder>
            <length>0.025</length>
            <radius>0.025</radius>
          </cylinder>
        </geometry>
        <material>
          <script>
            <name>Gazebo/Black</name>
            <uri>file://media/materials/scripts/gazebo.material</uri>
          </script>
        </material>
      </visual>
      <visual name='first_link_visual_1'>
        <pose frame=''>0 0.05 -0.01255 0 -0 0</pose>
        <geometry>
          <box>
            <size>0.05 0.1 0.025</size>
          </box>
        </geometry>
        <material>
          <script>
            <name>Gazebo/Black</name>
            <uri>file://media/materials/scripts/gazebo.material</uri>
          </script>
        </material>
      </visual>
      <visual name='first_link_visual_2'>
        <pose frame=''>0 0.15 0 0 -0 0</pose>
        <geometry>
          <box>
            <size>0.055 0.2 0.055</size>
          </box>
        </geometry>
        <!--material>
          <script>
            <name>Gazebo/white</name>
            <uri>file://media/materials/scripts/gazebo.material</uri>
          </script>
        </material-->
      </visual>
    </link>

    <link name='first_link_marker'>
      <pose frame=''>0 0.15 0.578 0 -0 0</pose>
      <visual name='first_link_marker'>
        <geometry>
          <box>
            <size>0.05 0.05 0.00001</size>
          </box>
        </geometry>
        <material>
          <script>
            <uri>model://wall_fb_1r1p/materials/scripts/marker5.material</uri>
            <uri>model://wall_fb_1r1p/materials/textures</uri>
            <name>myMarker5</name>
          </script>
        </material>
      </visual>
    </link>

    <joint name='first_marker_fixed' type='fixed'>
      <pose frame=''>0 0 0 0 -0 0</pose>
      <child>first_link_marker</child>
      <parent>first_link</parent>
      <axis>
        <dynamics>
          <damping>0</damping>
          <friction>0</friction>
          <spring_reference>0</spring_reference>
          <spring_stiffness>0</spring_stiffness>
        </dynamics>
        <use_parent_model_frame>1</use_parent_model_frame>
        <xyz>0 0 0</xyz>
      </axis>
    </joint>

    <joint name='anchor' type='fixed'>
      <child>wall</child>
      <parent>world</parent>
      <axis>
        <xyz>0 0 0</xyz>
      </axis>
    </joint>
    <link name='wall_dummy'>
      <gravity>0</gravity>
      <pose frame=''>0 0.275 0.55 0 -0 0</pose>
      <inertial>
        <pose frame=''>0 0 0 0 -0 0</pose>
        <mass>1</mass>
        <inertia>
          <ixx>1</ixx>
          <ixy>0</ixy>
          <ixz>0</ixz>
          <iyy>1</iyy>
          <iyz>0</iyz>
          <izz>1</izz>
        </inertia>
      </inertial>
      <collision name='wall_dummy_collision'>
        <pose frame=''>0 0 0 0 -0 0</pose>
        <geometry>
          <box>
            <size>0.05 0.05 0.05</size>
          </box>
        </geometry>
      </collision>
      <visual name='wall_dummy_visual'>
        <pose frame=''>0 0 0 0 -0 0</pose>
        <geometry>
          <box>
            <size>0.05 0.05 0.05</size>
          </box>
        </geometry>
        <material>
          <script>
            <name>Gazebo/RedTransparentOverlay</name>
            <uri>file://media/materials/scripts/gazebo.material</uri>
          </script>
        </material>
      </visual>
    </link>
    <joint name='first_link_handle_joint' type='fixed'>
      <pose frame=''>0 0 0 0 -0 0</pose>
      <child>wall_dummy</child>
      <parent>first_link</parent>
      <axis>
        <dynamics>
          <damping>0</damping>
          <friction>0</friction>
          <spring_reference>0</spring_reference>
          <spring_stiffness>0</spring_stiffness>
        </dynamics>
        <use_parent_model_frame>1</use_parent_model_frame>
        <xyz>0 0 0</xyz>
      </axis>
      <sensor name='first_link_wall_ft' type='force_torque'>
        <always_on>1</always_on>
        <update_rate>100</update_rate>
        <pose>0 0 0 0 0 0</pose>
        <plugin name='first_link_wall_ft_plugin' filename='libgazebo_yarp_forcetorque.so'>
          <yarpConfigurationFile>model://wall_fb_1r1p/conf/first_link_handle_ft.ini</yarpConfigurationFile>
          <frame>child</frame>
          <measured_direction>child_to_parent</measured_direction>
        </plugin>
      </sensor>
    </joint>
    <link name='wall'>
      <gravity>0</gravity>
      <pose frame=''>0 0.275 0.55 0 -0 0</pose>
      <inertial>
        <pose frame=''>0 0 0 0 -0 0</pose>
        <mass>1</mass>
        <inertia>
          <ixx>1</ixx>
          <ixy>0</ixy>
          <ixz>0</ixz>
          <iyy>1</iyy>
          <iyz>0</iyz>
          <izz>1</izz>
        </inertia>
      </inertial>
      <collision name='wall_dummy_collision'>
        <pose frame=''>0 0.05 0 0 -0 0</pose>
        <geometry>
          <box>
            <size>1 0.1 1</size>
          </box>
        </geometry>
      </collision>
      <visual name='wall_dummy_visual'>
        <pose frame=''>0 0.05 0 0 -0 0</pose>
        <geometry>
          <box>
            <size>1 0.1 1</size>
          </box>
        </geometry>
        <!--material>
          <script>
            <name>Gazebo/WhiteGlow</name>
            <uri>file://media/materials/scripts/gazebo.material</uri>
          </script>
        </material-->
      </visual>
    </link>
    <joint name='wall_joint' type='fixed'>
      <pose frame=''>0 0 0 0 -0 0</pose>
      <child>wall</child>
      <parent>wall_dummy</parent>
      <axis>
        <dynamics>
          <damping>0</damping>
          <friction>0</friction>
          <spring_reference>0</spring_reference>
          <spring_stiffness>0</spring_stiffness>
        </dynamics>
        <use_parent_model_frame>1</use_parent_model_frame>
        <xyz>0 0 0</xyz>
      </axis>
    </joint>
    <link name='middle_link'>
      <gravity>0</gravity>
      <pose frame=''>0 0 0.55 0 -0 1.256</pose>
      <inertial>
        <pose frame=''>0 0.1375 0 0 -0 0</pose>
        <mass>0.1</mass>
        <inertia>
          <ixx>0.001</ixx>
          <ixy>0</ixy>
          <ixz>0</ixz>
          <iyy>0.001</iyy>
          <iyz>0</iyz>
          <izz>0.001</izz>
        </inertia>
      </inertial>
      <collision name='middle_link_collision'>
        <pose frame=''>0 0 0.01255 0 -0 0</pose>
        <geometry>
          <cylinder>
            <length>0.025</length>
            <radius>0.025</radius>
          </cylinder>
        </geometry>
      </collision>
      <collision name='middle_link_collision_1'>
        <pose frame=''>0 0.05 0.0125 0 -0 0</pose>
        <geometry>
          <box>
            <size>0.05 0.1 0.025</size>
          </box>
        </geometry>
      </collision>
      <collision name='middle_link_collision_2'>
        <pose frame=''>0 0.15 0 0 -0 0</pose>
        <geometry>
          <box>
            <size>0.05 0.2 0.05</size>
          </box>
        </geometry>
      </collision>
      <visual name='middle_link_visual'>
        <pose frame=''>0 0 0.0125 0 -0 0</pose>
        <geometry>
          <cylinder>
            <length>0.025</length>
            <radius>0.025</radius>
          </cylinder>
        </geometry>
        <material>
          <script>
            <name>Gazebo/Black</name>
            <uri>file://media/materials/scripts/gazebo.material</uri>
          </script>
        </material>
      </visual>
      <visual name='middle_link_visual_1'>
        <pose frame=''>0 0.05 0.01255 0 -0 0</pose>
        <geometry>
          <box>
            <size>0.05 0.1 0.025</size>
          </box>
        </geometry>
        <material>
          <script>
            <name>Gazebo/Black</name>
            <uri>file://media/materials/scripts/gazebo.material</uri>
          </script>
        </material>
      </visual>
      <visual name='middle_link_visual_2'>
        <pose frame=''>0 0.15 0 0 -0 0</pose>
        <geometry>
          <box>
            <size>0.05 0.2 0.05</size>
          </box>
        </geometry>
        <material>
          <script>
            <name>Gazebo/Black</name>
            <uri>file://media/materials/scripts/gazebo.material</uri>
          </script>
        </material>
      </visual>
    </link>
    <joint name='first_joint' type='revolute'>
      <child>middle_link</child>
      <parent>first_link</parent>
      <axis>
        <xyz>0 0 1</xyz>
        <limit>
          <lower>0</lower>
          <!--upper>1.1775</upper-->
          <upper>3.8</upper>
          <effort>30</effort>
          <velocity>1</velocity>
        </limit>
        <dynamics>
          <spring_reference>0</spring_reference>
          <spring_stiffness>0</spring_stiffness>
        </dynamics>
        <use_parent_model_frame>1</use_parent_model_frame>
      </axis>
    </joint>
    <link name='second_link'>
      <gravity>0</gravity>
      <pose frame=''>0 0 0.55 0 -0 1.256</pose>
      <inertial>
        <pose frame=''>0 0.1375 0 0 -0 0</pose>
        <mass>2</mass>
        <inertia>
          <ixx>1</ixx>
          <ixy>0</ixy>
          <ixz>0</ixz>
          <iyy>1</iyy>
          <iyz>0</iyz>
          <izz>1</izz>
        </inertia>
      </inertial>
      <collision name='second_link_collision'>
        <pose frame=''>0 0.15 0 0 -0 0</pose>
        <geometry>
          <box>
            <size>0.05 0.2 0.05</size>
          </box>
        </geometry>
      </collision>
      <collision name='second_link_collision_1'>
        <pose frame=''>0 0.275 0 0 0 0</pose>
        <geometry>
          <box>
            <size>0.05 0.05 0.002</size>
          </box>
        </geometry>
      </collision>
      <visual name='second_link_visual'>
        <pose frame=''>0 0.15 0 0 -0 0</pose>
        <geometry>
          <box>
            <size>0.055 0.2 0.055</size>
          </box>
        </geometry>
        <!--material>
          <script>
            <name>Gazebo/white</name>
            <uri>file://media/materials/scripts/gazebo.material</uri>
          </script>
        </material-->
      </visual>
      <visual name='second_link_visual_1'>
        <pose frame=''>0 0.275 0 0 -0 0</pose>
        <geometry>
          <box>
            <size>0.05 0.05 0.002</size>
          </box>
        </geometry>
        <material>
          <script>
            <name>Gazebo/RedTransparentOverlay</name>
            <uri>file://media/materials/scripts/gazebo.material</uri>
          </script>
        </material>
      </visual>
    </link>

    <link name='second_link_marker'>
      <pose frame=''>-0.143 0.046 0.578 0 -0 1.256</pose>
      <visual name='second_link_marker'>
        <geometry>
          <box>
            <size>0.05 0.05 0.00001</size>
          </box>
        </geometry>
        <material>
          <script>
            <uri>model://wall_fb_1r1p/materials/scripts/marker2.material</uri>
            <uri>model://wall_fb_1r1p/materials/textures</uri>
            <name>myMarker2</name>
          </script>
        </material>
      </visual>
    </link>

    <joint name='second_marker_fixed' type='fixed'>
      <pose frame=''>0 0 0 0 -0 0</pose>
      <child>second_link_marker</child>
      <parent>second_link</parent>
      <axis>
        <dynamics>
          <damping>0</damping>
          <friction>0</friction>
          <spring_reference>0</spring_reference>
          <spring_stiffness>0</spring_stiffness>
        </dynamics>
        <use_parent_model_frame>1</use_parent_model_frame>
        <xyz>0 0 0</xyz>
      </axis>
    </joint>


    <joint name='second_joint' type='prismatic'>
      <child>second_link</child>
      <parent>middle_link</parent>
      <axis>
        <xyz>-0.950859 0.309623 0</xyz>
        <limit>
          <lower>0</lower>
          <upper>0.07</upper>
          <!--upper>0</upper-->
          <effort>30</effort>
          <velocity>1</velocity>
        </limit>
        <dynamics>
          <spring_reference>0</spring_reference>
          <spring_stiffness>0</spring_stiffness>
        </dynamics>
        <use_parent_model_frame>1</use_parent_model_frame>
      </axis>
    </joint>
    <link name='second_link_handle'>
      <gravity>0</gravity>
      <pose frame=''>-0.261 0.085 0.55 0 -0 1.256</pose>
      <inertial>
        <pose frame=''>0 0 0 0 -0 0</pose>
        <mass>0.0001</mass>
        <inertia>
          <ixx>0.0001</ixx>
          <ixy>0</ixy>
          <ixz>0</ixz>
          <iyy>0.0001</iyy>
          <iyz>0</iyz>
          <izz>0.0001</izz>
        </inertia>
      </inertial>
      <collision name='second_link_handle_collision'>
        <pose frame=''>0 0 0.045 0 -0 0</pose>
        <geometry>
          <cylinder>
            <length>0.1</length>
            <radius>0.01</radius>
          </cylinder>
        </geometry>
      </collision>
      <visual name='second_link_handle_visual'>
        <pose frame=''>0 0 0.045 0 -0 0</pose>
        <geometry>
          <cylinder>
            <length>0.1</length>
            <radius>0.01</radius>
          </cylinder>
        </geometry>
        <material>
          <script>
            <name>Gazebo/Black</name>
            <uri>file://media/materials/scripts/gazebo.material</uri>
          </script>
        </material>
      </visual>
    </link>
    <joint name='second_link_handle_joint' type='fixed'>
      <pose frame=''>0 0 0.0 0 -0 0</pose>
      <child>second_link_handle</child>
      <parent>second_link</parent>
      <axis>
        <dynamics>
          <damping>0</damping>
          <friction>0</friction>
          <spring_reference>0</spring_reference>
          <spring_stiffness>0</spring_stiffness>
        </dynamics>
        <use_parent_model_frame>1</use_parent_model_frame>
        <xyz>0 0 0</xyz>
      </axis>
      <sensor name='second_link_handle_ft' type='force_torque'>
        <always_on>1</always_on>
        <update_rate>100</update_rate>
        <pose>0 0 0 0 0 0</pose>
        <plugin name='second_link_handle_ft_plugin' filename='libgazebo_yarp_forcetorque.so'>
          <yarpConfigurationFile>model://wall_fb_1r1p/conf/second_link_handle_ft.ini</yarpConfigurationFile>
          <frame>child</frame>
          <measured_direction>child_to_parent</measured_direction>
        </plugin>
      </sensor>
    </joint>

    <!--Gazebo Yarp Plugin-->
    <plugin name="controlboard" filename="libgazebo_yarp_controlboard.so">
      <yarpConfigurationFile>model://wall_fb_1r1p/conf/gazebo_controlboard.ini</yarpConfigurationFile>
      <initialConfiguration>0.0 0.0</initialConfiguration>
    </plugin>

    <!--plugin name="world_interface" filename="libgazebo_yarp_worldinterface.so">
      <yarpConfigurationFile>model://wall_fb_1r1p/conf/gazebo_worldinterface.ini</yarpConfigurationFile>
    </plugin>

    <plugin name="object_attach" filename="libgazebo_yarp_objectattacher.so">
      <yarpConfigurationFile>model://wall_fb_1r1p/conf/gazebo_objectattacher.ini</yarpConfigurationFile>
    </plugin-->

    <!--plugin name='second_link_handle_ext_wrench' filename='libgazebo_yarp_externalwrench.so'>
      <robotNamefromConfigFile>model://wall_fb_1r1p/conf/gazebo_1r1p_robotname.ini</robotNamefromConfigFile>
    </plugin-->

    <plugin name='second_link_handle_multi_ext_wrench' filename='libgazebo_yarp_multiexternalwrench.so'>
      <robotNamefromConfigFile>model://wall_fb_1r1p/conf/gazebo_1r1p_robotname.ini</robotNamefromConfigFile>
    </plugin>

    <plugin name='access_link_pose' filename='libgazebo_yarp_accesslinkpose.so'>
      <yarpConfigurationFile>model://wall_fb_1r1p/conf/gazebo_accesslinkpose.ini</yarpConfigurationFile>
    </plugin>

    <link name="camera_link">
      <gravity>0</gravity>
      <!--pose frame=''>-0.1 0.2 0.8 0 1.57 0</pose--><!--This pose is perfect-->
      <!--pose frame=''>-0.1 0.2 0.5 0 1.57 0</pose-->
      <!--pose frame=''>-0.25 0.2 1 0 1.4 0</pose-->
      <!--pose frame=''>-0.25  0.2 1.25 0 1.4 0</pose-->
      <pose frame=''>0 0 1.2 0 1.57 0</pose>
      <visual name="camera_link_visual">
        <geometry>
          <box>
            <size>0.01 0.01 0.01</size>
          </box>
        </geometry>
      </visual>
      <sensor name="camera_sensor" type="camera">
        <camera>
          <horizontal_fov>1.5708</horizontal_fov>
          <image>
            <width>640</width>
            <height>480</height>
          </image>
          <clip>
            <near>0.1</near>
            <far>100</far>
          </clip>
          <distortion>
            <k1>-0.4</k1>
            <k2>-0.5</k2>
            <k3>-0.3</k3>
            <p1>-0.0</p1>
            <p2>-0.0</p2>
            <center>0.5 0.5</center>
          </distortion>
        </camera>
        <always_on>1</always_on>
        <update_rate>30</update_rate>
        <visualize>true</visualize>
        <plugin name="camera_plugin" filename="libgazebo_yarp_camera.so">
          <yarpConfigurationFile>model://wall_fb_1r1p/conf/camera.ini</yarpConfigurationFile>
        </plugin>
      </sensor>
    </link>
  </model>
</sdf>
