<?xml version="1.0" ?>
<!-- =================================================================================== -->
<!-- |    This document was autogenerated by xacro from model.xacro                    | -->
<!-- |    EDITING THIS FILE BY HAND IS NOT RECOMMENDED                                 | -->
<!-- =================================================================================== -->
<robot name="floating_base_1RDOF_2Link" xmlns:xacro="http://www.ros.org/wiki/xacro">
  <!-- =================================================================================== -->
  <!-- |    Author: Yeshasvi Tirupachuri                                                 | -->
  <!-- |    Date: 25 JULY 2016                                                           | -->
  <!-- |    Email: Yeshasvi.Tirupachuri@iit.it                                           | -->
  <!-- |    Institute: RBCS Department, Italian Institute of Technology, Genova          | -->
  <!-- |    Description: Xacro file for 2R Manipulator                                   | -->
  <!-- |    for URDF: rosrun xacro xacro model.xacro > model.urdf                        | -->
  <!-- |    for SDF: gz sdf -p model.urdf > model.sdf                                    | -->
  <!-- =================================================================================== -->
  <link name="world"/>
  <!--First Link-->
  <link name="first_link">
    <inertial>
      <origin rpy="0 0 0" xyz="0 0 0"/>
      <mass value="1"/>
      <inertia ixx="0.1" ixy="0" ixz="0" iyy="0.1" iyz="0" izz="0.1"/>
    </inertial>
    <!--First Link Small Cylinder - Front -->
    <visual>
      <origin rpy="0 0 0" xyz="0 0 -0.0125"/>
      <geometry>
        <cylinder length="0.025" radius="0.025"/>
        <material name="white">
          <color rgba="1.0 1.0 1.0 1.0"/>
        </material>
      </geometry>
    </visual>
    <collision>
      <origin rpy="0 0 0" xyz="0 0 -0.01255"/>
      <geometry>
        <cylinder length="0.025" radius="0.025"/>
      </geometry>
    </collision>
    <!--First Link Small Box - Front -->
    <visual>
      <origin rpy="0 0 0" xyz="0 0.05 -0.01255"/>
      <geometry>
        <box size="0.05 0.1 0.025"/>
        <material name="white">
          <color rgba="1.0 1.0 1.0 1.0"/>
        </material>
      </geometry>
    </visual>
    <collision>
      <origin rpy="0 0 0" xyz="0 0.05 -0.0125"/>
      <geometry>
        <box size="0.05 0.1 0.025"/>
      </geometry>
    </collision>
    <!--First Link Box-->
    <visual>
      <origin rpy="0 0 0" xyz="0 0.15 0"/>
      <geometry>
        <box size="0.05 0.2 0.05"/>
        <material name="white">
          <color rgba="1.0 1.0 1.0 1.0"/>
        </material>
      </geometry>
    </visual>
    <collision>
      <origin rpy="0 0 0" xyz="0 0.15 0"/>
      <geometry>
        <box size="0.05 0.2 0.05"/>
      </geometry>
    </collision>
  </link>
  <!--Second Link-->
  <link name="second_link">
    <inertial>
      <origin rpy="0 0 0" xyz="0 0 0"/>
      <mass value="1"/>
      <inertia ixx="0.1" ixy="0" ixz="0" iyy="0.1" iyz="0" izz="0.1"/>
    </inertial>
    <!--First Link Small Cylinder - Front -->
    <visual>
      <origin rpy="0 0 0" xyz="0 0 0.0125"/>
      <geometry>
        <cylinder length="0.025" radius="0.025"/>
        <material name="white">
          <color rgba="1.0 1.0 1.0 1.0"/>
        </material>
      </geometry>
    </visual>
    <collision>
      <origin rpy="0 0 0" xyz="0 0 0.01255"/>
      <geometry>
        <cylinder length="0.025" radius="0.025"/>
      </geometry>
    </collision>
    <!--First Link Small Box - Front -->
    <visual>
      <origin rpy="0 0 0" xyz="0 0.05 0.01255"/>
      <geometry>
        <box size="0.05 0.1 0.025"/>
        <material name="white">
          <color rgba="1.0 1.0 1.0 1.0"/>
        </material>
      </geometry>
    </visual>
    <collision>
      <origin rpy="0 0 0" xyz="0 0.05 0.0125"/>
      <geometry>
        <box size="0.05 0.1 0.025"/>
      </geometry>
    </collision>
    <!--First Link Box-->
    <visual>
      <origin rpy="0 0 0" xyz="0 0.15 0"/>
      <geometry>
        <box size="0.05 0.2 0.05"/>
        <material name="white">
          <color rgba="1.0 1.0 1.0 1.0"/>
        </material>
      </geometry>
    </visual>
    <collision>
      <origin rpy="0 0 0" xyz="0 0.15 0"/>
      <geometry>
        <box size="0.05 0.2 0.05"/>
      </geometry>
    </collision>
  </link>
  <!--Joints-->
  <joint name="anchor" type="floating">
    <parent link="world"/>
    <child link="first_link"/>
    <origin rpy="0 0 0" xyz="0 0 0.55"/>
  </joint>
  <joint name="first_joint" type="revolute">
    <parent link="first_link"/>
    <child link="second_link"/>
    <origin rpy="0 0 1.256" xyz="0 0 0"/>
    <axis xyz="0 0 1"/>
    <calibration rising="1"/>
    <dynamic damping="0.0" friction="0.0"/>
    <limit effort="30" lower="0" upper="1.57" velocity="1.0"/>
    <safety_controller k_position="15" k_velocity="10" soft_lower_limit="-1.5" soft_upper_limit="1.5"/>
  </joint>
</robot>

