<sdf version='1.6'>
  <model name='floating_base_1RDOF_2Link'>
    <link name='first_link'>
      <pose frame=''>0 0 0.55 0 -0 0</pose>
      <inertial>
        <pose frame=''>0 0 0 0 -0 0</pose>
        <mass>1</mass>
        <inertia>
          <ixx>0.001</ixx>
          <ixy>0</ixy>
          <ixz>0</ixz>
          <iyy>0.001</iyy>
          <iyz>0</iyz>
          <izz>0.001</izz>
        </inertia>
      </inertial>
      <collision name='first_link_collision'>
        <pose frame=''>0 0 -0.01255 0 -0 0</pose>
        <geometry>
          <cylinder>
            <length>0.025</length>
            <radius>0.025</radius>
          </cylinder>
        </geometry>
      </collision>
      <collision name='first_link_collision_1'>
        <pose frame=''>0 0.05 -0.0125 0 -0 0</pose>
        <geometry>
          <box>
            <size>0.05 0.1 0.025</size>
          </box>
        </geometry>
      </collision>
      <collision name='first_link_collision_2'>
        <pose frame=''>0 0.15 0 0 -0 0</pose>
        <geometry>
          <box>
            <size>0.05 0.2 0.05</size>
          </box>
        </geometry>
      </collision>
      <visual name='first_link_visual'>
        <pose frame=''>0 0 -0.0125 0 -0 0</pose>
        <geometry>
          <cylinder>
            <length>0.025</length>
            <radius>0.025</radius>
          </cylinder>
        </geometry>
        <material>
          <script>
            <name>Gazebo/Blue</name>
            <uri>file://media/materials/scripts/gazebo.material</uri>
          </script>
        </material>
      </visual>
      <visual name='first_link_visual_1'>
        <pose frame=''>0 0.05 -0.01255 0 -0 0</pose>
        <geometry>
          <box>
            <size>0.05 0.1 0.025</size>
          </box>
        </geometry>
        <material>
          <script>
            <name>Gazebo/Blue</name>
            <uri>file://media/materials/scripts/gazebo.material</uri>
          </script>
        </material>
      </visual>
      <visual name='first_link_visual_2'>
        <pose frame=''>0 0.15 0 0 -0 0</pose>
        <geometry>
          <box>
            <size>0.05 0.2 0.05</size>
          </box>
        </geometry>
        <material>
          <script>
            <name>Gazebo/Blue</name>
            <uri>file://media/materials/scripts/gazebo.material</uri>
          </script>
        </material>
      </visual>
    </link>
    <link name='second_link'>
      <pose frame=''>0 0 0.55 0 -0 1.256</pose>
      <inertial>
        <pose frame=''>0 0 0 0 -0 0</pose>
        <mass>1</mass>
        <inertia>
          <ixx>0.001</ixx>
          <ixy>0</ixy>
          <ixz>0</ixz>
          <iyy>0.001</iyy>
          <iyz>0</iyz>
          <izz>0.001</izz>
        </inertia>
      </inertial>
      <collision name='second_link_collision'>
        <pose frame=''>0 0 0.01255 0 -0 0</pose>
        <geometry>
          <cylinder>
            <length>0.025</length>
            <radius>0.025</radius>
          </cylinder>
        </geometry>
      </collision>
      <collision name='second_link_collision_1'>
        <pose frame=''>0 0.05 0.0125 0 -0 0</pose>
        <geometry>
          <box>
            <size>0.05 0.1 0.025</size>
          </box>
        </geometry>
      </collision>
      <collision name='second_link_collision_2'>
        <pose frame=''>0 0.15 0 0 -0 0</pose>
        <geometry>
          <box>
            <size>0.05 0.2 0.05</size>
          </box>
        </geometry>
      </collision>
      <visual name='second_link_visual'>
        <pose frame=''>0 0 0.0125 0 -0 0</pose>
        <geometry>
          <cylinder>
            <length>0.025</length>
            <radius>0.025</radius>
          </cylinder>
        </geometry>
        <material>
          <script>
            <name>Gazebo/Orange</name>
            <uri>file://media/materials/scripts/gazebo.material</uri>
          </script>
        </material>
      </visual>
      <visual name='second_link_visual_1'>
        <pose frame=''>0 0.05 0.01255 0 -0 0</pose>
        <geometry>
          <box>
            <size>0.05 0.1 0.025</size>
          </box>
        </geometry>
        <material>
          <script>
            <name>Gazebo/Orange</name>
            <uri>file://media/materials/scripts/gazebo.material</uri>
          </script>
        </material>
      </visual>
      <visual name='second_link_visual_2'>
        <pose frame=''>0 0.15 0 0 -0 0</pose>
        <geometry>
          <box>
            <size>0.05 0.2 0.05</size>
          </box>
        </geometry>
        <material>
          <script>
            <name>Gazebo/Orange</name>
            <uri>file://media/materials/scripts/gazebo.material</uri>
          </script>
        </material>
      </visual>
    </link>
    <joint name='first_joint' type='revolute'>
      <child>second_link</child>
      <parent>first_link</parent>
      <axis>
        <xyz>0 0 1</xyz>
        <limit>
          <lower>0</lower>
          <upper>1.57</upper>
          <effort>30</effort>
          <velocity>1</velocity>
        </limit>
        <dynamics>
          <spring_reference>0</spring_reference>
          <spring_stiffness>0</spring_stiffness>
        </dynamics>
        <use_parent_model_frame>1</use_parent_model_frame>
      </axis>
    </joint>
  </model>
</sdf>
