<?xml version="1.0" ?>
<!-- =================================================================================== -->
<!-- |    This document was autogenerated by xacro from model.xacro                    | -->
<!-- |    EDITING THIS FILE BY HAND IS NOT RECOMMENDED                                 | -->
<!-- =================================================================================== -->
<robot name="2r_manipulator_scaled_down" xmlns:xacro="http://www.ros.org/wiki/xacro">
  <!-- =================================================================================== -->
  <!-- |    Author: Yeshasvi Tirupachuri                                                 | -->
  <!-- |    Date: 22 JULY 2016                                                           | -->
  <!-- |    Email: Yeshasvi.Tirupachuri@iit.it                                           | -->
  <!-- |    Institute: RBCS Department, Italian Institute of Technology, Genova          | -->
  <!-- |    Description: Xacro file for 2R Manipulator                                   | -->
  <!-- |    for URDF: rosrun xacro xacro model.xacro > model.urdf                        | -->
  <!-- |    for SDF: gz sdf -p model.urdf > model.sdf                                    | -->
  <!-- =================================================================================== -->
  <!--XACRO: Axis Rotation - 180 Degree/ Pi Radians-->
  <!--XACRO: Small Rectangle-->
  <!--XACRO: Small Cylinder-->
  <!--XACRO: Base Rectangle-->
  <!--XACRO: First Link Rectangle-->
  <!--XACRO: Second Link Rectangle-->
  <!--XACRO: Handle Link Cylinder-->
  <link name="world"/>
  <!--Base Link is at the Origin-->
  <link name="base_link">
    <inertial>
      <origin rpy="0 0 0" xyz="0 0 0"/>
      <mass value="1"/>
      <inertia ixx="0.1" ixy="0" ixz="0" iyy="0.1" iyz="0" izz="0.1"/>
    </inertial>
    <!--Base Link Box-->
    <visual>
      <origin rpy="0 0 0" xyz="0 0 0"/>
      <geometry>
        <box size="0.3 0.05 0.05"/>
      </geometry>
      <material name="white">
        <color rgba="1.0 1.0 1.0 1.0"/>
      </material>
    </visual>
    <collision>
      <origin rpy="0 0 0" xyz="0 0 0"/>
      <geometry>
        <box size="0.3 0.05 0.05"/>
      </geometry>
    </collision>
    <!--Base Link Small Box-->
    <visual>
      <origin rpy="0 0 0" xyz="0 0.025 -0.0125"/>
      <geometry>
        <box size="0.05 0.1 0.025"/>
      </geometry>
      <material name="white">
        <color rgba="1.0 1.0 1.0 1.0"/>
      </material>
    </visual>
    <collision>
      <origin rpy="0 0 0" xyz="0 0.025 -0.0125"/>
      <geometry>
        <box size="0.05 0.1 0.025"/>
      </geometry>
    </collision>
    <!--Base Link Small Cylinder-->
    <visual>
      <origin rpy="0 0 0" xyz="0 0.075 -0.0125"/>
      <geometry>
        <cylinder length="0.025" radius="0.025"/>
      </geometry>
      <material name="white">
        <color rgba="1.0 1.0 1.0 1.0"/>
      </material>
    </visual>
    <collision>
      <origin rpy="0 0 0" xyz="0 0.075 -0.0125"/>
      <geometry>
        <cylinder length="0.025" radius="0.025"/>
      </geometry>
    </collision>
  </link>
  <!--First Link-->
  <link name="first_link">
    <inertial>
      <origin rpy="0 0 0" xyz="0 0.1375 -0.00625"/>
      <mass value="1"/>
      <inertia ixx="0.1" ixy="0" ixz="0" iyy="0.1" iyz="0" izz="0.1"/>
    </inertial>
    <!--First Link Small Cylinder - Front -->
    <visual>
      <origin rpy="0 0 0.785" xyz="0 0 0.00625"/>
      <geometry>
        <cylinder length="0.025" radius="0.025"/>
        <material name="white">
          <color rgba="1.0 1.0 1.0 1.0"/>
        </material>
      </geometry>
    </visual>
    <collision>
      <origin rpy="0 0 0.785" xyz="0 0 0.00625"/>
      <geometry>
        <cylinder length="0.025" radius="0.025"/>
      </geometry>
    </collision>
    <!--First Link Small Box - Front -->
    <visual>
      <origin rpy="0 0 0" xyz="0 0.05 0.00625"/>
      <geometry>
        <box size="0.05 0.1 0.025"/>
        <material name="white">
          <color rgba="1.0 1.0 1.0 1.0"/>
        </material>
      </geometry>
    </visual>
    <collision>
      <origin rpy="0 0 0" xyz="0 0.05 0.00625"/>
      <geometry>
        <box size="0.05 0.1 0.025"/>
      </geometry>
    </collision>
    <!--First Link Box-->
    <visual>
      <origin rpy="0 0 0" xyz="0 0.15 -0.00625"/>
      <geometry>
        <box size="0.05 0.2 0.05"/>
        <material name="white">
          <color rgba="1.0 1.0 1.0 1.0"/>
        </material>
      </geometry>
    </visual>
    <collision>
      <origin rpy="0 0 0" xyz="0 0.15 -0.00625"/>
      <geometry>
        <box size="0.05 0.2 0.05"/>
      </geometry>
    </collision>
    <!--First Link Small Box - Back -->
    <visual>
      <origin rpy="0 0 0" xyz="0 0.25 -0.01875"/>
      <geometry>
        <box size="0.05 0.1 0.025"/>
        <material name="white">
          <color rgba="1.0 1.0 1.0 1.0"/>
        </material>
      </geometry>
    </visual>
    <collision>
      <origin rpy="0 0 0" xyz="0 0.25 -0.01875"/>
      <geometry>
        <box size="0.05 0.1 0.025"/>
      </geometry>
    </collision>
    <!--First Link Small Cylinder - Back -->
    <visual>
      <origin rpy="0 0 0" xyz="0 0.3 -0.01875"/>
      <geometry>
        <cylinder length="0.025" radius="0.025"/>
        <material name="white">
          <color rgba="1.0 1.0 1.0 1.0"/>
        </material>
      </geometry>
    </visual>
    <collision>
      <origin rpy="0 0 0" xyz="0 0.3 -0.01875"/>
      <geometry>
        <cylinder length="0.025" radius="0.025"/>
      </geometry>
    </collision>
  </link>
  <!--Second Link -->
  <link name="second_link">
    <inertial>
      <origin rpy="0 0 0" xyz="0 0.1375 -0.0125"/>
      <mass value="1"/>
      <inertia ixx="0.1" ixy="0" ixz="0" iyy="0.1" iyz="0" izz="0.1"/>
    </inertial>
    <!--Second Link Small Cylinder - Front -->
    <visual>
      <origin rpy="0 0 0" xyz="0 0 0"/>
      <geometry>
        <cylinder length="0.025" radius="0.025"/>
        <material name="white">
          <color rgba="1.0 1.0 1.0 1.0"/>
        </material>
      </geometry>
    </visual>
    <collision>
      <origin rpy="0 0 0" xyz="0 0 0"/>
      <geometry>
        <cylinder length="0.025" radius="0.025"/>
      </geometry>
    </collision>
    <!--Second Link Small Box - Front -->
    <visual>
      <origin rpy="0 0 0" xyz="0 0.05 0"/>
      <geometry>
        <box size="0.05 0.1 0.025"/>
        <material name="white">
          <color rgba="1.0 1.0 1.0 1.0"/>
        </material>
      </geometry>
    </visual>
    <collision>
      <origin rpy="0 0 0" xyz="0 0.05 0"/>
      <geometry>
        <box size="0.05 0.1 0.025"/>
      </geometry>
    </collision>
    <!--Second Link Box-->
    <visual>
      <origin rpy="0 0 0" xyz="0 0.15 -0.0125"/>
      <geometry>
        <box size="0.05 0.2 0.05"/>
        <material name="white">
          <color rgba="1.0 1.0 1.0 1.0"/>
        </material>
      </geometry>
    </visual>
    <collision>
      <origin rpy="0 0 0" xyz="0 0.15 -0.0125"/>
      <geometry>
        <box size="0.05 0.2 0.05"/>
      </geometry>
    </collision>
    <!--Second Link Small Box - Back -->
    <visual>
      <origin rpy="0 0 0" xyz="0 0.25 -0.025"/>
      <geometry>
        <box size="0.05 0.1 0.025"/>
        <material name="white">
          <color rgba="1.0 1.0 1.0 1.0"/>
        </material>
      </geometry>
    </visual>
    <collision>
      <origin rpy="0 0 0" xyz="0 0.25 -0.025"/>
      <geometry>
        <box size="0.05 0.1 0.025"/>
      </geometry>
    </collision>
    <!--Second Link Small Cylinder - Back -->
    <visual>
      <origin rpy="0 0 0" xyz="0 0.3 -0.025"/>
      <geometry>
        <cylinder length="0.025" radius="0.025"/>
        <material name="white">
          <color rgba="1.0 1.0 1.0 1.0"/>
        </material>
      </geometry>
    </visual>
    <collision>
      <origin rpy="0 0 0" xyz="0 0.3 -0.025"/>
      <geometry>
        <cylinder length="0.025" radius="0.025"/>
      </geometry>
    </collision>
  </link>
  <!--Handle Link-->
  <link name="handle_link">
    <inertial>
      <origin rpy="0 0 0" xyz="0 0 0.0125"/>
      <mass value="1"/>
      <inertia ixx="0.1" ixy="0" ixz="0" iyy="0.1" iyz="0" izz="0.1"/>
    </inertial>
    <visual>
      <origin rpy="0 0 0" xyz="0 0 0.025"/>
      <geometry>
        <cylinder length="0.1" radius="0.0125"/>
        <material name="white">
          <color rgba="1.0 1.0 1.0 1.0"/>
        </material>
      </geometry>
    </visual>
    <collision>
      <origin rpy="0 0 0" xyz="0 0 0.025"/>
      <geometry>
        <cylinder length="0.1" radius="0.0125"/>
      </geometry>
    </collision>
  </link>
  <!--Joints-->
  <joint name="anchor" type="fixed">
    <parent link="world"/>
    <child link="base_link"/>
    <origin rpy="0 0 0" xyz="0 0 0.55"/>
    <axis xyz="0 0 0"/>
  </joint>
  <joint name="first_joint" type="revolute">
    <parent link="base_link"/>
    <child link="first_link"/>
    <origin rpy="0 0 0.785" xyz="0 0.075 0.00625"/>
    <axis xyz="0 0 1"/>
    <calibration rising="1"/>
    <dynamic damping="0.0" friction="0.0"/>
    <limit effort="30" lower="-1.57" upper="0.3925" velocity="1.0"/>
    <safety_controller k_position="15" k_velocity="10" soft_lower_limit="-1.5" soft_upper_limit="1.5"/>
  </joint>
  <joint name="second_joint" type="revolute">
    <parent link="first_link"/>
    <child link="second_link"/>
    <origin rpy="0 0 -1.57" xyz="0 0.3 0.00625"/>
    <axis xyz="0 0 1"/>
    <calibration rising="1"/>
    <dynamic damping="0.0" friction="0.0"/>
    <limit effort="30" lower="-0.3925" upper="0.3925" velocity="1.0"/>
    <safety_controller k_position="15" k_velocity="10" soft_lower_limit="-1.5" soft_upper_limit="1.5"/>
  </joint>
  <joint name="handle_joint" type="revolute">
    <parent link="second_link"/>
    <child link="handle_link"/>
    <origin rpy="0 0 0" xyz="0 0.3 -0.00625"/>
    <axis xyz="0 0 1"/>
    <calibration rising="1"/>
    <dynamic damping="0.0" friction="0.0"/>
    <limit effort="30" lower="-3.14" upper="3.14" velocity="1.0"/>
    <safety_controller k_position="15" k_velocity="10" soft_lower_limit="-1.5" soft_upper_limit="1.5"/>
  </joint>
  <!--This is for Gazebo Yarp Plugin-->
  <!--plugin name="controlboard" filename="libgazebo_yarp_controlboard.so">
       <yarpConfigurationFile>model://manipulator2r/conf/gazebo_controlboard.ini</yarpConfigurationFile>
       <initialConfiguration>0.0 0.0</initialConfiguration>
     </plugin-->
</robot>

