<sdf version='1.6'>
  <model name='2r_manipulator_scaled_down'>
    <link name='base_link'>
      <pose frame=''>0 0 0.55 0 -0 0</pose>
      <inertial>
        <pose frame=''>0 0 0 0 -0 0</pose>
        <mass>1</mass>
        <inertia>
          <ixx>0.1</ixx>
          <ixy>0</ixy>
          <ixz>0</ixz>
          <iyy>0.1</iyy>
          <iyz>0</iyz>
          <izz>0.1</izz>
        </inertia>
      </inertial>
      <collision name='base_link_collision'>
        <pose frame=''>0 0 0 0 -0 0</pose>
        <geometry>
          <box>
            <size>0.3 0.05 0.05</size>
          </box>
        </geometry>
      </collision>
      <collision name='base_link_collision_1'>
        <pose frame=''>0 0.025 -0.0125 0 -0 0</pose>
        <geometry>
          <box>
            <size>0.05 0.1 0.025</size>
          </box>
        </geometry>
      </collision>
      <collision name='base_link_collision_2'>
        <pose frame=''>0 0.075 -0.0125 0 -0 0</pose>
        <geometry>
          <cylinder>
            <length>0.025</length>
            <radius>0.025</radius>
          </cylinder>
        </geometry>
      </collision>
      <visual name='base_link_visual'>
        <pose frame=''>0 0 0 0 -0 0</pose>
        <geometry>
          <box>
            <size>0.3 0.05 0.05</size>
          </box>
        </geometry>
        <material>
          <script>
            <name>Gazebo/FlatBlack</name>
            <uri>file://media/materials/scripts/gazebo.material</uri>
          </script>
        </material>
      </visual>
      <visual name='base_link_visual_1'>
        <pose frame=''>0 0.025 -0.0125 0 -0 0</pose>
        <geometry>
          <box>
            <size>0.05 0.1 0.025</size>
          </box>
        </geometry>
        <material>
          <script>
            <name>Gazebo/FlatBlack</name>
            <uri>file://media/materials/scripts/gazebo.material</uri>
          </script>
        </material>
      </visual>
      <visual name='base_link_visual_2'>
        <pose frame=''>0 0.075 -0.0125 0 -0 0</pose>
        <geometry>
          <cylinder>
            <length>0.025</length>
            <radius>0.025</radius>
          </cylinder>
        </geometry>
        <material>
          <script>
            <name>Gazebo/FlatBlack</name>
            <uri>file://media/materials/scripts/gazebo.material</uri>
          </script>
        </material>
      </visual>
    </link>
    <joint name='anchor' type='revolute'>
      <child>base_link</child>
      <parent>world</parent>
      <axis>
        <limit>
          <lower>0</lower>
          <upper>0</upper>
        </limit>
        <dynamics>
          <damping>0</damping>
          <friction>0</friction>
          <spring_reference>0</spring_reference>
          <spring_stiffness>0</spring_stiffness>
        </dynamics>
        <use_parent_model_frame>1</use_parent_model_frame>
        <xyz>0 0 1</xyz>
      </axis>
    </joint>
    <link name='first_link'>
      <pose frame=''>0 0.075 0.55625 0 -0 0.785</pose>
      <inertial>
        <pose frame=''>0 0.1375 -0.00625 0 -0 0</pose>
        <mass>1</mass>
        <inertia>
          <ixx>0.1</ixx>
          <ixy>0</ixy>
          <ixz>0</ixz>
          <iyy>0.1</iyy>
          <iyz>0</iyz>
          <izz>0.1</izz>
        </inertia>
      </inertial>
      <collision name='first_link_collision'>
        <pose frame=''>0 0 0.00625 0 -0 0.785</pose>
        <geometry>
          <cylinder>
            <length>0.025</length>
            <radius>0.025</radius>
          </cylinder>
        </geometry>
      </collision>
      <collision name='first_link_collision_1'>
        <pose frame=''>0 0.05 0.00625 0 -0 0</pose>
        <geometry>
          <box>
            <size>0.05 0.1 0.025</size>
          </box>
        </geometry>
      </collision>
      <collision name='first_link_collision_2'>
        <pose frame=''>0 0.15 -0.00625 0 -0 0</pose>
        <geometry>
          <box>
            <size>0.05 0.2 0.05</size>
          </box>
        </geometry>
      </collision>
      <collision name='first_link_collision_3'>
        <pose frame=''>0 0.25 -0.01875 0 -0 0</pose>
        <geometry>
          <box>
            <size>0.05 0.1 0.025</size>
          </box>
        </geometry>
      </collision>
      <collision name='first_link_collision_4'>
        <pose frame=''>0 0.3 -0.01875 0 -0 0</pose>
        <geometry>
          <cylinder>
            <length>0.025</length>
            <radius>0.025</radius>
          </cylinder>
        </geometry>
      </collision>
      <visual name='first_link_visual'>
        <pose frame=''>0 0 0.00625 0 -0 0.785</pose>
        <geometry>
          <cylinder>
            <length>0.025</length>
            <radius>0.025</radius>
          </cylinder>
        </geometry>
        <material>
          <script>
            <name>Gazebo/Yellow</name>
            <uri>file://media/materials/scripts/gazebo.material</uri>
          </script>
        </material>
      </visual>
      <visual name='first_link_visual_1'>
        <pose frame=''>0 0.05 0.00625 0 -0 0</pose>
        <geometry>
          <box>
            <size>0.05 0.1 0.025</size>
          </box>
        </geometry>
        <material>
          <script>
            <name>Gazebo/Yellow</name>
            <uri>file://media/materials/scripts/gazebo.material</uri>
          </script>
        </material>
      </visual>
      <visual name='first_link_visual_2'>
        <pose frame=''>0 0.15 -0.00625 0 -0 0</pose>
        <geometry>
          <box>
            <size>0.05 0.2 0.05</size>
          </box>
        </geometry>
        <material>
          <script>
            <name>Gazebo/Yellow</name>
            <uri>file://media/materials/scripts/gazebo.material</uri>
          </script>
        </material>
      </visual>
      <visual name='first_link_visual_3'>
        <pose frame=''>0 0.25 -0.01875 0 -0 0</pose>
        <geometry>
          <box>
            <size>0.05 0.1 0.025</size>
          </box>
        </geometry>
        <material>
          <script>
            <name>Gazebo/Yellow</name>
            <uri>file://media/materials/scripts/gazebo.material</uri>
          </script>
        </material>
      </visual>
      <visual name='first_link_visual_4'>
        <pose frame=''>0 0.3 -0.01875 0 -0 0</pose>
        <geometry>
          <cylinder>
            <length>0.025</length>
            <radius>0.025</radius>
          </cylinder>
        </geometry>
        <material>
          <script>
            <name>Gazebo/Yellow</name>
            <uri>file://media/materials/scripts/gazebo.material</uri>
          </script>
        </material>
      </visual>
    </link>
    <joint name='joint1' type='revolute'>
      <child>first_link</child>
      <parent>base_link</parent>
      <axis>
        <xyz>0 0 1</xyz>
        <limit>
          <lower>-1.57</lower>
          <upper>0.3925</upper>
          <effort>30</effort>
          <velocity>1</velocity>
        </limit>
        <dynamics>
          <spring_reference>0</spring_reference>
          <spring_stiffness>0</spring_stiffness>
        </dynamics>
        <use_parent_model_frame>1</use_parent_model_frame>
      </axis>
    </joint>
    <link name='second_link'>
      <pose frame=''>-0.212048 0.287216 0.5625 0 0 -0.785</pose>
      <inertial>
        <pose frame=''>0 0.1375 -0.0125 0 -0 0</pose>
        <mass>1</mass>
        <inertia>
          <ixx>0.1</ixx>
          <ixy>0</ixy>
          <ixz>0</ixz>
          <iyy>0.1</iyy>
          <iyz>0</iyz>
          <izz>0.1</izz>
        </inertia>
      </inertial>
      <collision name='second_link_collision'>
        <pose frame=''>0 0 0 0 -0 0</pose>
        <geometry>
          <cylinder>
            <length>0.025</length>
            <radius>0.025</radius>
          </cylinder>
        </geometry>
      </collision>
      <collision name='second_link_collision_1'>
        <pose frame=''>0 0.05 0 0 -0 0</pose>
        <geometry>
          <box>
            <size>0.05 0.1 0.025</size>
          </box>
        </geometry>
      </collision>
      <collision name='second_link_collision_2'>
        <pose frame=''>0 0.15 -0.0125 0 -0 0</pose>
        <geometry>
          <box>
            <size>0.05 0.2 0.05</size>
          </box>
        </geometry>
      </collision>
      <collision name='second_link_collision_3'>
        <pose frame=''>0 0.25 -0.025 0 -0 0</pose>
        <geometry>
          <box>
            <size>0.05 0.1 0.025</size>
          </box>
        </geometry>
      </collision>
      <collision name='second_link_collision_4'>
        <pose frame=''>0 0.3 -0.025 0 -0 0</pose>
        <geometry>
          <cylinder>
            <length>0.025</length>
            <radius>0.025</radius>
          </cylinder>
        </geometry>
      </collision>
      <visual name='second_link_visual'>
        <pose frame=''>0 0 0 0 -0 0</pose>
        <geometry>
          <cylinder>
            <length>0.025</length>
            <radius>0.025</radius>
          </cylinder>
        </geometry>
        <material>
          <script>
            <name>Gazebo/SkyBlue</name>
            <uri>file://media/materials/scripts/gazebo.material</uri>
          </script>
        </material>
      </visual>
      <visual name='second_link_visual_1'>
        <pose frame=''>0 0.05 0 0 -0 0</pose>
        <geometry>
          <box>
            <size>0.05 0.1 0.025</size>
          </box>
        </geometry>
        <material>
          <script>
            <name>Gazebo/SkyBlue</name>
            <uri>file://media/materials/scripts/gazebo.material</uri>
          </script>
        </material>
      </visual>
      <visual name='second_link_visual_2'>
        <pose frame=''>0 0.15 -0.0125 0 -0 0</pose>
        <geometry>
          <box>
            <size>0.05 0.2 0.05</size>
          </box>
        </geometry>
        <material>
          <script>
            <name>Gazebo/SkyBlue</name>
            <uri>file://media/materials/scripts/gazebo.material</uri>
          </script>
        </material>
      </visual>
      <visual name='second_link_visual_3'>
        <pose frame=''>0 0.25 -0.025 0 -0 0</pose>
        <geometry>
          <box>
            <size>0.05 0.1 0.025</size>
          </box>
        </geometry>
        <material>
          <script>
            <name>Gazebo/SkyBlue</name>
            <uri>file://media/materials/scripts/gazebo.material</uri>
          </script>
        </material>
      </visual>
      <visual name='second_link_visual_4'>
        <pose frame=''>0 0.3 -0.025 0 -0 0</pose>
        <geometry>
          <cylinder>
            <length>0.025</length>
            <radius>0.025</radius>
          </cylinder>
        </geometry>
        <material>
          <script>
            <name>Gazebo/SkyBlue</name>
            <uri>file://media/materials/scripts/gazebo.material</uri>
          </script>
        </material>
      </visual>
    </link>
    <joint name='joint2' type='revolute'>
      <child>second_link</child>
      <parent>first_link</parent>
      <axis>
        <xyz>0 0 1</xyz>
        <limit>
          <lower>-0.3925</lower>
          <upper>0.3925</upper>
          <effort>30</effort>
          <velocity>1</velocity>
        </limit>
        <dynamics>
          <spring_reference>0</spring_reference>
          <spring_stiffness>0</spring_stiffness>
        </dynamics>
        <use_parent_model_frame>1</use_parent_model_frame>
      </axis>
    </joint>
    <link name='handle_link'>
      <pose frame=''>0 0.499433 0.55625 0 0 -0.785</pose>
      <inertial>
        <pose frame=''>0 0 0.0125 0 -0 0</pose>
        <mass>1</mass>
        <inertia>
          <ixx>0.1</ixx>
          <ixy>0</ixy>
          <ixz>0</ixz>
          <iyy>0.1</iyy>
          <iyz>0</iyz>
          <izz>0.1</izz>
        </inertia>
      </inertial>
      <collision name='handle_link_collision'>
        <pose frame=''>0 0 0.025 0 -0 0</pose>
        <geometry>
          <cylinder>
            <length>0.1</length>
            <radius>0.0125</radius>
          </cylinder>
        </geometry>
      </collision>
      <visual name='handle_link_visual'>
        <pose frame=''>0 0 0.025 0 -0 0</pose>
        <geometry>
          <cylinder>
            <length>0.1</length>
            <radius>0.0125</radius>
          </cylinder>
        </geometry>
        <material>
          <script>
            <name>Gazebo/Orange</name>
            <uri>file://media/materials/scripts/gazebo.material</uri>
          </script>
        </material>
      </visual>
    </link>
    <joint name='joint3' type='revolute'>
      <child>handle_link</child>
      <parent>second_link</parent>
      <axis>
        <xyz>0 0 1</xyz>
        <limit>
          <lower>-3.14</lower>
          <upper>3.14</upper>
          <effort>30</effort>
          <velocity>1</velocity>
        </limit>
        <dynamics>
          <spring_reference>0</spring_reference>
          <spring_stiffness>0</spring_stiffness>
        </dynamics>
        <use_parent_model_frame>1</use_parent_model_frame>
      </axis>
    </joint>

    <!--Gazebo Yarp Plugin-->
    <plugin name="controlboard" filename="libgazebo_yarp_controlboard.so">
      <yarpConfigurationFile>model://2r_manipulator_scaled_down/conf/gazebo_controlboard.ini</yarpConfigurationFile>
      <initialConfiguration>0.0 0.0</initialConfiguration>
    </plugin>

  </model>
</sdf>
