<?xml version="1.0" ?>
<robot name="1r_2link">
  <joint name="1r_2link__anchor" type="fixed">
    <parent link="1r_2link__world"/>
    <child link="1r_2link__first_link_handle"/>
    <origin rpy="0  0  0" xyz="0    0    0.55"/>
    <axis xyz="0  0  0"/>
    <!--limit effort="0.0" lower="0.0" upper="0.0" velocity="0.0"/-->
  </joint>
  <joint name="1r_2link__first_link_handle_ft_joint" type="fixed">
    <parent link="1r_2link__first_link_handle"/>
    <child link="1r_2link__first_link"/>
    <origin rpy="0  0  0" xyz="0.025  0     0"/>
    <axis xyz="0  0  0"/>
    <!--limit effort="0.0" lower="0.0" upper="0.0" velocity="0.0"/-->
  </joint>
  <joint name="1r_2link__first_joint" type="revolute">
    <parent link="1r_2link__first_link"/>
    <child link="1r_2link__second_link"/>
    <origin rpy="0  0 -2" xyz="0.25  0    0"/>
    <axis xyz="0  0  1"/>
    <limit effort="30.0" lower="0.0" upper="3.14" velocity="10.0"/>
  </joint>
  <joint name="1r_2link__second_link_handle_ft_joint" type="fixed">
    <parent link="1r_2link__second_link"/>
    <child link="1r_2link__second_link_handle"/>
    <origin rpy="0  0  0" xyz="2.75020000e-01   5.00000000e-05   0.00000000e+00"/>
    <axis xyz="0  0  0"/>
    <!--limit effort="0.0" lower="0.0" upper="0.0" velocity="0.0"/-->
  </joint>
  <link name="1r_2link__world">
    <inertial>
      <mass value="0"/>
      <origin rpy="0  0  0" xyz="0  0  0"/>
      <inertia ixx="0" ixy="0" ixz="0" iyy="0" iyz="0" izz="0"/>
    </inertial>
  </link>
  <link name="1r_2link__first_link_handle">
    <inertial>
      <mass value="1"/>
      <origin rpy="0  0  0" xyz="0  0  0"/>
      <inertia ixx="0.00001" ixy="0" ixz="0" iyy="0.00001" iyz="0" izz="0.00001"/>
    </inertial>
    <collision name="1r_2link__first_link_handle_collision">
      <origin rpy="0  0  0" xyz="0  0  0"/>
      <geometry>
        <cylinder length="0.1" radius="0.01"/>
      </geometry>
    </collision>
    <visual name="1r_2link__first_link_handle_visual">
      <origin rpy="0  0  0" xyz="0  0  0"/>
      <geometry>
        <cylinder length="0.1" radius="0.01"/>
      </geometry>
    </visual>
  </link>
  <link name="1r_2link__first_link">
    <inertial>
      <mass value="1"/>
      <origin rpy="0  0  0" xyz="0.1  0   0"/>
      <inertia ixx="0.0004" ixy="0" ixz="0" iyy="0.0034" iyz="0" izz="0.0034"/>
    </inertial>
    <collision name="1r_2link__first_link_collision_1">
      <origin rpy="0  0  0" xyz="0.1  0   0"/>
      <geometry>
        <box size="0.2 0.05 0.05"/>
      </geometry>
    </collision>
    <collision name="1r_2link__first_link_collision_2">
      <origin rpy="0  0  0" xyz="0.2     0     -0.0125"/>
      <geometry>
        <box size="0.1 0.05 0.025"/>
      </geometry>
    </collision>
    <collision name="1r_2link__fisrt_link_collision_3">
      <origin rpy="0  0  0" xyz="0.25    0     -0.0125"/>
      <geometry>
        <cylinder length="0.025" radius="0.025"/>
      </geometry>
    </collision>
    <visual name="1r_2link__first_link_visual">
      <origin rpy="0  0  0" xyz="-0.025  0     0"/>
      <geometry>
        <box size="0.05 0.05 0.0002"/>
      </geometry>
    </visual>
    <visual name="1r_2link__first_link_visual_1">
      <origin rpy="0  0  0" xyz="0.1  0   0"/>
      <geometry>
        <box size="0.2 0.05 0.05"/>
      </geometry>
    </visual>
    <visual name="1r_2link__first_link_visual_2">
      <origin rpy="0  0  0" xyz="0.2     0     -0.0125"/>
      <geometry>
        <box size="0.1 0.05 0.025"/>
      </geometry>
    </visual>
    <visual name="1r_2link__first_link_visual_3">
      <origin rpy="0  0  0" xyz="0.25    0     -0.0125"/>
      <geometry>
        <cylinder length="0.025" radius="0.025"/>
      </geometry>
    </visual>
  </link>
  <link name="1r_2link__second_link">
    <inertial>
      <mass value="1"/>
      <origin rpy="0  0  0" xyz="0.15  0    0"/>
      <inertia ixx="0.0004" ixy="0" ixz="0" iyy="0.0034" iyz="0" izz="0.0034"/>
    </inertial>
    <collision name="1r_2link__second_link_collision">
      <origin rpy="0  0  0" xyz="0      0      0.0125"/>
      <geometry>
        <cylinder length="0.025" radius="0.025"/>
      </geometry>
    </collision>
    <collision name="1r_2link__second_link_collision_1">
      <origin rpy="0  0  0" xyz="0.05    0      0.0125"/>
      <geometry>
        <box size="0.1 0.05 0.025"/>
      </geometry>
    </collision>
    <collision name="1r_2link__second_link_collision_2">
      <origin rpy="0  0  0" xyz="0.15  0    0"/>
      <geometry>
        <box size="0.2 0.05 0.05"/>
      </geometry>
    </collision>
    <collision name="1r_2link__second_link_collision_3">
      <origin rpy="0  0  0" xyz="0.275  0     0"/>
      <geometry>
        <box size="0.05 0.05 0.0002"/>
      </geometry>
    </collision>
    <visual name="1r_2link__second_link_visual">
      <origin rpy="0  0  0" xyz="0      0      0.0125"/>
      <geometry>
        <cylinder length="0.025" radius="0.025"/>
      </geometry>
    </visual>
    <visual name="1r_2link__second_link_visual_1">
      <origin rpy="0  0  0" xyz="0.05    0      0.0125"/>
      <geometry>
        <box size="0.1 0.05 0.025"/>
      </geometry>
    </visual>
    <visual name="1r_2link__second_link_visual_2">
      <origin rpy="0  0  0" xyz="0.15  0    0"/>
      <geometry>
        <box size="0.2 0.05 0.05"/>
      </geometry>
    </visual>
    <visual name="1r_2link__second_link_visual_3">
      <origin rpy="0  0  0" xyz="0.275  0     0"/>
      <geometry>
        <box size="0.05 0.05 0.0002"/>
      </geometry>
    </visual>
  </link>
  <link name="1r_2link__second_link_handle">
    <inertial>
      <mass value="1"/>
      <origin rpy="0  0  0" xyz="0  0  0"/>
      <inertia ixx="0.00001" ixy="0" ixz="0" iyy="0.00001" iyz="0" izz="0.00001"/>
    </inertial>
    <collision name="1r_2link__second_link_handle_collision">
      <origin rpy="0  0  0" xyz="0  0  0"/>
      <geometry>
        <cylinder length="0.1" radius="0.01"/>
      </geometry>
    </collision>
    <visual name="1r_2link__second_link_handle_visual">
      <origin rpy="0  0  0" xyz="0  0  0"/>
      <geometry>
        <cylinder length="0.1" radius="0.01"/>
      </geometry>
    </visual>
  </link>
  <gazebo reference="1r_2link__first_link_handle_ft_joint">
    <sensor name="first_link_ft" type="force_torque">
      <always_on>1</always_on>
      <update_rate>100</update_rate>
      <force_torque>
        <frame>child</frame>
        <measure_direction>child_to_parent</measure_direction>
      </force_torque>
    </sensor>
  </gazebo>
  <sensor name="first_link_ft" type="force_torque">
    <parent joint="1r_2link__first_link_handle_ft_joint"/>
    <force_torque>
      <frame>child</frame>
      <measure_direction>child_to_parent</measure_direction>
    </force_torque>
  </sensor>
  <gazebo reference="1r_2link__second_link_handle_ft_joint">
    <sensor name="second_link_ft" type="force_torque">
      <always_on>1</always_on>
      <update_rate>100</update_rate>
      <force_torque>
        <frame>child</frame>
        <measure_direction>child_to_parent</measure_direction>
      </force_torque>
    </sensor>
  </gazebo>
  <sensor name="second_link_ft" type="force_torque">
    <parent joint="1r_2link__second_link_handle_ft_joint"/>
    <force_torque>
      <frame>child</frame>
      <measure_direction>child_to_parent</measure_direction>
    </force_torque>
  </sensor>
</robot>
