<sdf version='1.6'>
  <model name='floating_base_1R1P_2Link'>
    <link name='first_link'>
      <gravity>0</gravity>
      <pose frame=''>0 0 0.55 0 -0 0</pose>
      <inertial>
        <pose frame=''>0 0.1375 0 0 -0 0</pose>
        <mass>0.1</mass>
        <inertia>
          <ixx>0.001</ixx>
          <ixy>0</ixy>
          <ixz>0</ixz>
          <iyy>0.001</iyy>
          <iyz>0</iyz>
          <izz>0.001</izz>
        </inertia>
      </inertial>
      <collision name='first_link_collision'>
        <pose frame=''>0 0 -0.01255 0 -0 0</pose>
        <geometry>
          <cylinder>
            <length>0.025</length>
            <radius>0.025</radius>
          </cylinder>
        </geometry>
      </collision>
      <collision name='first_link_collision_1'>
        <pose frame=''>0 0.05 -0.0125 0 -0 0</pose>
        <geometry>
          <box>
            <size>0.05 0.1 0.025</size>
          </box>
        </geometry>
      </collision>
      <collision name='first_link_collision_2'>
        <pose frame=''>0 0.15 0 0 -0 0</pose>
        <geometry>
          <box>
            <size>0.05 0.2 0.05</size>
          </box>
        </geometry>
      </collision>
      <collision name='first_link_collision_4'>
        <pose frame=''>0 0.275 0 0 0 0</pose>
        <geometry>
          <box>
            <size>0.05 0.05 0.002</size>
          </box>
        </geometry>
      </collision>
      <collision name='first_link_collision_5'>
        <pose frame=''>0 0.275 0.045 0 -0 0</pose>
        <geometry>
          <cylinder>
            <length>0.1</length>
            <radius>0.01</radius>
          </cylinder>
        </geometry>
      </collision>
      <visual name='first_link_visual'>
        <pose frame=''>0 0 -0.0125 0 -0 0</pose>
        <geometry>
          <cylinder>
            <length>0.025</length>
            <radius>0.025</radius>
          </cylinder>
        </geometry>
        <material>
          <script>
            <name>Gazebo/Black</name>
            <uri>file://media/materials/scripts/gazebo.material</uri>
          </script>
        </material>
      </visual>
      <visual name='first_link_visual_1'>
        <pose frame=''>0 0.05 -0.01255 0 -0 0</pose>
        <geometry>
          <box>
            <size>0.05 0.1 0.025</size>
          </box>
        </geometry>
        <material>
          <script>
            <name>Gazebo/Black</name>
            <uri>file://media/materials/scripts/gazebo.material</uri>
          </script>
        </material>
      </visual>
      <visual name='first_link_visual_2'>
        <pose frame=''>0 0.15 0 0 -0 0</pose>
        <geometry>
          <box>
            <size>0.055 0.2 0.055</size>
          </box>
        </geometry>
        <material>
          <script>
            <name>Gazebo/Yellow</name>
            <uri>file://media/materials/scripts/gazebo.material</uri>
          </script>
        </material>
      </visual>

      <visual name='first_link_dummy'>
        <pose frame=''>0 0.15 0.028 0 -0 0</pose>
        <geometry>
          <box>
            <size>0.045 0.045 0.00001</size>
          </box>
        </geometry>
        <material>
          <script>
            <uri>model://floating_base_1R1P_2Link/materials/scripts/marker1.material</uri>
            <uri>model://floating_base_1R1P_2Link/materials/textures</uri>
            <name>myMarker1</name>
          </script>
        </material>
      </visual>

      <visual name='first_link_visual_4'>
        <pose frame=''>0 0.275 0 0 -0 0</pose>
        <geometry>
          <box>
            <size>0.05 0.05 0.002</size>
          </box>
        </geometry>
        <material>
          <script>
            <name>Gazebo/RedTransparentOverlay</name>
            <uri>file://media/materials/scripts/gazebo.material</uri>
          </script>
        </material>
      </visual>

      <visual name='first_link_visual_5'>
        <pose frame=''>0 0.275 0.045 0 -0 0</pose>
        <geometry>
          <cylinder>
            <length>0.1</length>
            <radius>0.01</radius>
          </cylinder>
        </geometry>
        <material>
          <script>
            <name>Gazebo/Black</name>
            <uri>file://media/materials/scripts/gazebo.material</uri>
          </script>
        </material>
      </visual>


    </link>
    <!--joint name='anchor' type='revolute'>
      <child>first_link</child>
      <parent>world</parent>
      <axis>
        <limit>
          <lower>0</lower>
          <upper>0</upper>
        </limit>
        <dynamics>
          <damping>0</damping>
          <friction>0</friction>
          <spring_reference>0</spring_reference>
          <spring_stiffness>0</spring_stiffness>
        </dynamics>
        <use_parent_model_frame>1</use_parent_model_frame>
        <xyz>0 0 1</xyz>
      </axis>
    </joint!-->
    <link name='middle_link'>
      <gravity>0</gravity>
      <pose frame=''>0 0 0.55 0 -0 1.256</pose>
      <inertial>
        <pose frame=''>0 0.1375 0 0 -0 0</pose>
        <mass>0.1</mass>
        <inertia>
          <ixx>0.001</ixx>
          <ixy>0</ixy>
          <ixz>0</ixz>
          <iyy>0.001</iyy>
          <iyz>0</iyz>
          <izz>0.001</izz>
        </inertia>
      </inertial>
      <collision name='middle_link_collision'>
        <pose frame=''>0 0 0.01255 0 -0 0</pose>
        <geometry>
          <cylinder>
            <length>0.025</length>
            <radius>0.025</radius>
          </cylinder>
        </geometry>
      </collision>
      <collision name='middle_link_collision_1'>
        <pose frame=''>0 0.05 0.0125 0 -0 0</pose>
        <geometry>
          <box>
            <size>0.05 0.1 0.025</size>
          </box>
        </geometry>
      </collision>
      <collision name='middle_link_collision_2'>
        <pose frame=''>0 0.15 0 0 -0 0</pose>
        <geometry>
          <box>
            <size>0.05 0.2 0.05</size>
          </box>
        </geometry>
      </collision>
      <visual name='middle_link_visual'>
        <pose frame=''>0 0 0.0125 0 -0 0</pose>
        <geometry>
          <cylinder>
            <length>0.025</length>
            <radius>0.025</radius>
          </cylinder>
        </geometry>
        <material>
          <script>
            <name>Gazebo/Black</name>
            <uri>file://media/materials/scripts/gazebo.material</uri>
          </script>
        </material>
      </visual>
      <visual name='middle_link_visual_1'>
        <pose frame=''>0 0.05 0.01255 0 -0 0</pose>
        <geometry>
          <box>
            <size>0.05 0.1 0.025</size>
          </box>
        </geometry>
        <material>
          <script>
            <name>Gazebo/Black</name>
            <uri>file://media/materials/scripts/gazebo.material</uri>
          </script>
        </material>
      </visual>
      <visual name='middle_link_visual_2'>
        <pose frame=''>0 0.15 0 0 -0 0</pose>
        <geometry>
          <box>
            <size>0.05 0.2 0.05</size>
          </box>
        </geometry>
        <material>
          <script>
            <name>Gazebo/Black</name>
            <uri>file://media/materials/scripts/gazebo.material</uri>
          </script>
        </material>
      </visual>
    </link>
    <joint name='first_joint' type='revolute'>
      <child>middle_link</child>
      <parent>first_link</parent>
      <axis>
        <xyz>0 0 1</xyz>
        <limit>
          <lower>0</lower>
          <upper>1.1775</upper>
          <effort>30</effort>
          <velocity>1</velocity>
        </limit>
        <dynamics>
          <spring_reference>0</spring_reference>
          <spring_stiffness>0</spring_stiffness>
        </dynamics>
        <use_parent_model_frame>1</use_parent_model_frame>
      </axis>
    </joint>
    <link name='second_link'>
      <gravity>0</gravity>
      <pose frame=''>0 0 0.55 0 -0 1.256</pose>
      <inertial>
        <pose frame=''>0 0.1375 0 0 -0 0</pose>
        <mass>0.1</mass>
        <inertia>
          <ixx>0.001</ixx>
          <ixy>0</ixy>
          <ixz>0</ixz>
          <iyy>0.001</iyy>
          <iyz>0</iyz>
          <izz>0.001</izz>
        </inertia>
      </inertial>
      <collision name='second_link_collision'>
        <pose frame=''>0 0.15 0 0 -0 0</pose>
        <geometry>
          <box>
            <size>0.05 0.2 0.05</size>
          </box>
        </geometry>
      </collision>
      <collision name='second_link_collision_2'>
        <pose frame=''>0 0.275 0 0 0 0</pose>
        <geometry>
          <box>
            <size>0.05 0.05 0.002</size>
          </box>
        </geometry>
      </collision>
      <collision name='second_link_collision_3'>
        <pose frame=''>0 0.275 0.045 0 -0 0</pose>
        <geometry>
          <cylinder>
            <length>0.1</length>
            <radius>0.01</radius>
          </cylinder>
        </geometry>
      </collision>
      <visual name='second_link_visual'>
        <pose frame=''>0 0.15 0 0 -0 0</pose>
        <geometry>
          <box>
            <size>0.055 0.2 0.055</size>
          </box>
        </geometry>
        <material>
          <script>
            <name>Gazebo/Yellow</name>
            <uri>file://media/materials/scripts/gazebo.material</uri>
          </script>
        </material>
      </visual>

      <visual name='second_link_dummy'>
        <pose frame=''>0 0.15 0.0275 0 -0 0</pose>
        <geometry>
          <box>
            <size>0.045 0.045 0.00001</size>
          </box>
        </geometry>
        <material>
          <script>
            <uri>model://floating_base_1R1P_2Link/materials/scripts/marker5.material</uri>
            <uri>model://floating_base_1R1P_2Link/materials/textures</uri>
            <name>myMarker5</name>
          </script>
        </material>
      </visual>

      <visual name='second_link_visual_2'>
        <pose frame=''>0 0.275 0 0 -0 0</pose>
        <geometry>
          <box>
            <size>0.05 0.05 0.002</size>
          </box>
        </geometry>
        <material>
          <script>
            <name>Gazebo/RedTransparentOverlay</name>
            <uri>file://media/materials/scripts/gazebo.material</uri>
          </script>
        </material>
      </visual>

      <visual name='second_link_visual_3'>
        <pose frame=''>0 0.275 0.045 0 -0 0</pose>
        <geometry>
          <cylinder>
            <length>0.1</length>
            <radius>0.01</radius>
          </cylinder>
        </geometry>
        <material>
          <script>
            <name>Gazebo/Black</name>
            <uri>file://media/materials/scripts/gazebo.material</uri>
          </script>
        </material>
      </visual>

    </link>
    <joint name='second_joint' type='prismatic'>
      <child>second_link</child>
      <parent>middle_link</parent>
      <axis>
        <xyz>-0.950859 0.309623 0</xyz>
        <limit>
          <lower>0</lower>
          <upper>0.07</upper>
          <effort>30</effort>
          <velocity>1</velocity>
        </limit>
        <dynamics>
          <spring_reference>0</spring_reference>
          <spring_stiffness>0</spring_stiffness>
        </dynamics>
        <use_parent_model_frame>1</use_parent_model_frame>
      </axis>
    </joint>
  </model>
</sdf>
