<sdf version=1.6>
  <model name='marker_camera'>
    <link name='marker_link'>
      <gravity>0</gravity>
      <pose frame=''>0 0 0.1 0 0 0</pose>
      <visual name='marker_link_visual'>
      <pose frame=''>0 0 0 0 0 0</pose>
        <geometry>
          <box>
            <size>0.08 0.08 0.08</size>
          </box>
        </geometry>
      </visual>

      <visual name='marker_link_visual_1'>
      <pose frame=''>0 0 0.0405 0 0 0</pose>
        <geometry>
          <box>
            <size>0.05 0.05 0.0001</size>
          </box>
        </geometry>
        <material>
          <script>
            <uri>model://marker_camera/materials/scripts/marker5.material</uri>
            <uri>model://marker_camera/materials/textures</uri>
            <name>myMarker5</name>
          </script>
        </material>
      </visual>
    </link>

    <joint name='anchor' type='fixed'>
      <child>marker_link</child>
      <parent>world</parent>
      <axis>
        <xyz>0 0 0</xyz>
      </axis>
    </joint>

    <link name='first_dummy_link'>
      <gravity>0</gravity>
      <pose frame=''>0 0 0.2 0 0 0</pose>
    </link>
    <link name='second_dummy_link'>
      <gravity>0</gravity>
      <pose frame=''>0 0 0.2 0 0 0</pose>
    </link>

    <joint name='first_joint' type='revolute'>
      <child>first_dummy_link</child>
      <parent>marker_link</parent>
      <axis>
        <xyz>0 0 1</xyz>
        <limit>
          <lower>0</lower>
          <upper>3.14</upper>
          <effort>30</effort>
          <velocity>10</velocity>
        </limit>
        <dynamics>
          <spring_reference>0</spring_reference>
          <spring_stiffness>0</spring_stiffness>
        </dynamics>
        <use_parent_model_frame>1</use_parent_model_frame>
      </axis>
    </joint>

    <joint name='second_joint' type='prismatic'>
      <child>second_dummy_link</child>
      <parent>first_dummy_link</parent>
      <axis>
        <xyz>0 0 -1</xyz>
        <limit>
          <lower>0</lower>
          <upper>0.5</upper>
          <effort>30</effort>
          <velocity>10</velocity>
        </limit>
        <dynamics>
          <spring_reference>0</spring_reference>
          <spring_stiffness>0</spring_stiffness>
        </dynamics>
        <use_parent_model_frame>1</use_parent_model_frame>
      </axis>
    </joint>

    <joint name='camera_fixed_joint' type='fixed'>
      <child>camera_link</child>
      <parent>second_dummy_link</parent>
      <axis>
        <xyz>0 0 0</xyz>
      </axis>
    </joint>

    <link name='camera_link'>
      <gravity>0</gravity>
      <pose frame=''>0 0 0.5 0 1.57 0</pose>
      <visual name='camera_link_visual'>
        <geometry>
          <box>
            <size>0.01 0.01 0.01</size>
          </box>
        </geometry>
      </visual>
      <sensor name="camera_sensor" type="camera">
        <camera>
          <horizontal_fov>1.5708</horizontal_fov>
          <image>
            <width>640</width>
            <height>480</height>
          </image>
          <clip>
            <near>0.1</near>
            <far>100</far>
          </clip>
          <distortion>
            <k1>-0.4</k1>
            <k2>-0.5</k2>
            <k3>-0.3</k3>
            <p1>-0.0</p1>
            <p2>-0.0</p2>
            <center>0.5 0.5</center>
          </distortion>
        </camera>
        <always_on>1</always_on>
        <update_rate>30</update_rate>
        <visualize>true</visualize>
        <plugin name="camera_plugin" filename="libgazebo_yarp_camera.so">
          <yarpConfigurationFile>model://marker_camera/conf/camera.ini</yarpConfigurationFile>
        </plugin>
      </sensor>
    </link>

    <plugin name="controlboard" filename="libgazebo_yarp_controlboard.so">
      <yarpConfigurationFile>model://marker_camera/conf/gazebo_controlboard.ini</yarpConfigurationFile>
      <initialConfiguration>0.0 0.0 0.0</initialConfiguration>
    </plugin>

  </model>
</sdf>
